<?xml version="1.0" ?>
<!-- =================================================================================== -->
<!-- |    This document was autogenerated by xacro from /home/winston/catkin_ws/src/ros2_programme_simulator/mobile_manipulator_moveit_config/urdf/husky_ur5e_robot.urdf.xacro | -->
<!-- |    EDITING THIS FILE BY HAND IS NOT RECOMMENDED                                 | -->
<!-- =================================================================================== -->
<robot name="husky_ur5e">
  <gazebo>
    <plugin filename="libgazebo_ros_control.so" name="ros_control">
      <!--robotNamespace>/</robotNamespace-->
      <!--robotSimType>gazebo_ros_control/DefaultRobotHWSim</robotSimType-->
    </plugin>
    <!--
    <plugin name="gazebo_ros_power_monitor_controller" filename="libgazebo_ros_power_monitor.so">
      <alwaysOn>true</alwaysOn>
      <updateRate>1.0</updateRate>
      <timeout>5</timeout>
      <powerStateTopic>power_state</powerStateTopic>
      <powerStateRate>10.0</powerStateRate>
      <fullChargeCapacity>87.78</fullChargeCapacity>     
      <dischargeRate>-474</dischargeRate>
      <chargeRate>525</chargeRate>
      <dischargeVoltage>15.52</dischargeVoltage>
      <chargeVoltage>16.41</chargeVoltage>
    </plugin>
-->
  </gazebo>
  <material name="dark_grey">
    <color rgba="0.2 0.2 0.2 1.0"/>
  </material>
  <material name="medium_grey">
    <color rgba="0.6 0.6 0.6 1.0"/>
  </material>
  <material name="light_grey">
    <color rgba="0.8 0.8 0.8 1.0"/>
  </material>
  <material name="yellow">
    <color rgba="0.8 0.8 0.0 1.0"/>
  </material>
  <material name="black">
    <color rgba="0.15 0.15 0.15 1.0"/>
  </material>
  <material name="white">
    <color rgba="1.0 1.0 1.0 1.0"/>
  </material>
  <material name="red">
    <color rgba="1.0 0.0 0.0 1.0"/>
  </material>
  <!--gazebo>
    <plugin name="imu_plugin" filename="libgazebo_ros_imu.so">
      <alwaysOn>true</alwaysOn>
      <bodyName>base_footprint</bodyName>
      <topicName>imu</topicName>
      <serviceName>imu_service</serviceName>
      <gaussianNoise>0.0</gaussianNoise>
      <updateRate>20.0</updateRate>
    </plugin>
  </gazebo-->
  <material name="zed_mat">
    <color rgba="0.8 0.8 0.8 0.8"/>
  </material>
  <material name="zedm_mat">
    <color rgba="0 0 0 0.9"/>
  </material>
  <material name="zed2_mat">
    <color rgba="0.25 0.25 0.25 0.99"/>
  </material>
  <material name="zed2i_mat">
    <color rgba="0.25 0.25 0.25 0.99"/>
  </material>
  <!--gazebo>
    <plugin name="imu_plugin" filename="libgazebo_ros_imu.so">
      <alwaysOn>true</alwaysOn>
      <bodyName>base_footprint</bodyName>
      <topicName>imu</topicName>
      <serviceName>imu_service</serviceName>
      <gaussianNoise>0.0</gaussianNoise>
      <updateRate>20.0</updateRate>
    </plugin>
  </gazebo-->
  <!--property name="shoulder_height" value="0.089159" /-->
  <!--property name="shoulder_offset" value="0.13585" /-->
  <!-- shoulder_offset - elbow_offset + wrist_1_length = 0.10915 -->
  <!--property name="upper_arm_length" value="0.42500" /-->
  <!--property name="elbow_offset" value="0.1197" /-->
  <!-- CAD measured -->
  <!--property name="forearm_length" value="0.39225" /-->
  <!--property name="wrist_1_length" value="0.093" /-->
  <!-- CAD measured -->
  <!--property name="wrist_2_length" value="0.09465" /-->
  <!-- In CAD this distance is 0.930, but in the spec it is 0.09465 -->
  <!--property name="wrist_3_length" value="0.0823" /-->
  <!-- manually measured -->
  <link name="base_link">
    <visual>
      <geometry>
        <mesh filename="package://mobile_manipulator_moveit_config/meshes/ur5e/visual/base.dae"/>
      </geometry>
      <material name="LightGrey">
        <color rgba="0.7 0.7 0.7 1.0"/>
      </material>
    </visual>
    <collision>
      <geometry>
        <mesh filename="package://mobile_manipulator_moveit_config/meshes/ur5e/collision/base.stl"/>
      </geometry>
    </collision>
    <!-- <xacro:cylinder_inertial radius="0.06" length="0.05" mass="${base_mass}">
        <origin xyz="0.0 0.0 0.0" rpy="0 0 0" />
      </xacro:cylinder_inertial> -->
  </link>
  <joint name="shoulder_pan_joint" type="revolute">
    <parent link="base_link"/>
    <child link="shoulder_link"/>
    <origin rpy="0.0 0.0 0.0" xyz="0.0 0.0 0.163"/>
    <axis xyz="0 0 1"/>
    <limit effort="150.0" lower="-3.141592653589793" upper="0.2617993877991494" velocity="3.14"/>
    <dynamics damping="0.0" friction="0.0"/>
  </joint>
  <link name="shoulder_link">
    <visual>
      <geometry>
        <mesh filename="package://mobile_manipulator_moveit_config/meshes/ur5e/visual/shoulder.dae"/>
      </geometry>
      <material name="LightGrey">
        <color rgba="0.7 0.7 0.7 1.0"/>
      </material>
    </visual>
    <collision>
      <geometry>
        <mesh filename="package://mobile_manipulator_moveit_config/meshes/ur5e/collision/shoulder.stl"/>
      </geometry>
    </collision>
    <inertial>
      <mass value="3.7"/>
      <origin rpy="0 0 0" xyz="0.0 0.0 0.0"/>
      <inertia ixx="0.010267495893" ixy="0.0" ixz="0.0" iyy="0.010267495893" iyz="0.0" izz="0.00666"/>
    </inertial>
  </link>
  <joint name="shoulder_lift_joint" type="revolute">
    <parent link="shoulder_link"/>
    <child link="upper_arm_link"/>
    <origin rpy="0.0 1.5707963267948966 0.0" xyz="0.0 0.138 0.0"/>
    <axis xyz="0 1 0"/>
    <limit effort="150.0" lower="-3.141592653589793" upper="3.141592653589793" velocity="3.14"/>
    <dynamics damping="0.0" friction="0.0"/>
  </joint>
  <link name="upper_arm_link">
    <visual>
      <geometry>
        <mesh filename="package://mobile_manipulator_moveit_config/meshes/ur5e/visual/upperarm.dae"/>
      </geometry>
      <material name="LightGrey">
        <color rgba="0.7 0.7 0.7 1.0"/>
      </material>
    </visual>
    <collision>
      <geometry>
        <mesh filename="package://mobile_manipulator_moveit_config/meshes/ur5e/collision/upperarm.stl"/>
      </geometry>
    </collision>
    <inertial>
      <mass value="8.393"/>
      <origin rpy="0 0 0" xyz="0.0 0.0 0.2125"/>
      <inertia ixx="0.1338857818623325" ixy="0.0" ixz="0.0" iyy="0.1338857818623325" iyz="0.0" izz="0.0151074"/>
    </inertial>
  </link>
  <joint name="elbow_joint" type="revolute">
    <parent link="upper_arm_link"/>
    <child link="forearm_link"/>
    <origin rpy="0.0 0.0 0.0" xyz="0.0 -0.131 0.425"/>
    <axis xyz="0 1 0"/>
    <limit effort="150.0" lower="-3.141592653589793" upper="3.141592653589793" velocity="3.14"/>
    <dynamics damping="0.0" friction="0.0"/>
  </joint>
  <link name="forearm_link">
    <visual>
      <geometry>
        <mesh filename="package://mobile_manipulator_moveit_config/meshes/ur5e/visual/forearm.dae"/>
      </geometry>
      <material name="LightGrey">
        <color rgba="0.7 0.7 0.7 1.0"/>
      </material>
    </visual>
    <collision>
      <geometry>
        <mesh filename="package://mobile_manipulator_moveit_config/meshes/ur5e/collision/forearm.stl"/>
      </geometry>
    </collision>
    <inertial>
      <mass value="2.275"/>
      <origin rpy="0 0 0" xyz="0.0 0.0 0.196"/>
      <inertia ixx="0.031179620861480004" ixy="0.0" ixz="0.0" iyy="0.031179620861480004" iyz="0.0" izz="0.004095"/>
    </inertial>
  </link>
  <joint name="wrist_1_joint" type="revolute">
    <parent link="forearm_link"/>
    <child link="wrist_1_link"/>
    <origin rpy="0.0 1.5707963267948966 0.0" xyz="0.0 0.0 0.392"/>
    <axis xyz="0 1 0"/>
    <limit effort="28.0" lower="-3.141592653589793" upper="3.141592653589793" velocity="6.28"/>
    <dynamics damping="0.0" friction="0.0"/>
  </joint>
  <link name="wrist_1_link">
    <visual>
      <geometry>
        <mesh filename="package://mobile_manipulator_moveit_config/meshes/ur5e/visual/wrist1.dae"/>
      </geometry>
      <material name="LightGrey">
        <color rgba="0.7 0.7 0.7 1.0"/>
      </material>
    </visual>
    <collision>
      <geometry>
        <mesh filename="package://mobile_manipulator_moveit_config/meshes/ur5e/collision/wrist1.stl"/>
      </geometry>
    </collision>
    <inertial>
      <mass value="1.219"/>
      <origin rpy="0 0 0" xyz="0.0 0.127 0.0"/>
      <inertia ixx="0.0025598989760400002" ixy="0.0" ixz="0.0" iyy="0.0025598989760400002" iyz="0.0" izz="0.0021942"/>
    </inertial>
  </link>
  <joint name="wrist_2_joint" type="revolute">
    <parent link="wrist_1_link"/>
    <child link="wrist_2_link"/>
    <origin rpy="0.0 0.0 0.0" xyz="0.0 0.127 0.0"/>
    <axis xyz="0 0 1"/>
    <limit effort="28.0" lower="-3.141592653589793" upper="3.141592653589793" velocity="6.28"/>
    <dynamics damping="0.0" friction="0.0"/>
  </joint>
  <link name="wrist_2_link">
    <visual>
      <geometry>
        <mesh filename="package://mobile_manipulator_moveit_config/meshes/ur5e/visual/wrist2.dae"/>
      </geometry>
      <material name="LightGrey">
        <color rgba="0.7 0.7 0.7 1.0"/>
      </material>
    </visual>
    <collision>
      <geometry>
        <mesh filename="package://mobile_manipulator_moveit_config/meshes/ur5e/collision/wrist2.stl"/>
      </geometry>
    </collision>
    <inertial>
      <mass value="1.219"/>
      <origin rpy="0 0 0" xyz="0.0 0.0 0.1"/>
      <inertia ixx="0.0025598989760400002" ixy="0.0" ixz="0.0" iyy="0.0025598989760400002" iyz="0.0" izz="0.0021942"/>
    </inertial>
  </link>
  <joint name="wrist_3_joint" type="revolute">
    <parent link="wrist_2_link"/>
    <child link="wrist_3_link"/>
    <origin rpy="0.0 0.0 0.0" xyz="0.0 0.0 0.1"/>
    <axis xyz="0 1 0"/>
    <limit effort="28.0" lower="-3.141592653589793" upper="3.141592653589793" velocity="6.28"/>
    <dynamics damping="0.0" friction="0.0"/>
  </joint>
  <link name="wrist_3_link">
    <visual>
      <geometry>
        <mesh filename="package://mobile_manipulator_moveit_config/meshes/ur5e/visual/wrist3.dae"/>
      </geometry>
      <material name="LightGrey">
        <color rgba="0.7 0.7 0.7 1.0"/>
      </material>
    </visual>
    <collision>
      <geometry>
        <mesh filename="package://mobile_manipulator_moveit_config/meshes/ur5e/collision/wrist3.stl"/>
      </geometry>
    </collision>
    <inertial>
      <mass value="0.1879"/>
      <origin rpy="1.5707963267948966 0 0" xyz="0.0 0.0771 0.0"/>
      <inertia ixx="9.890410052167731e-05" ixy="0.0" ixz="0.0" iyy="9.890410052167731e-05" iyz="0.0" izz="0.0001321171875"/>
    </inertial>
  </link>
  <joint name="ee_fixed_joint" type="fixed">
    <parent link="wrist_3_link"/>
    <child link="ee_link"/>
    <origin rpy="0.0 0.0 1.5707963267948966" xyz="0.0 0.1 0.0"/>
  </joint>
  <link name="ee_link">
    <collision>
      <geometry>
        <box size="0.01 0.01 0.01"/>
      </geometry>
      <origin rpy="0 0 0" xyz="-0.01 0 0"/>
    </collision>
  </link>
  <transmission name="shoulder_pan_trans">
    <type>transmission_interface/SimpleTransmission</type>
    <joint name="shoulder_pan_joint">
      <hardwareInterface>hardware_interface/PositionJointInterface</hardwareInterface>
    </joint>
    <actuator name="shoulder_pan_motor">
      <mechanicalReduction>1</mechanicalReduction>
    </actuator>
  </transmission>
  <transmission name="shoulder_lift_trans">
    <type>transmission_interface/SimpleTransmission</type>
    <joint name="shoulder_lift_joint">
      <hardwareInterface>hardware_interface/PositionJointInterface</hardwareInterface>
    </joint>
    <actuator name="shoulder_lift_motor">
      <mechanicalReduction>1</mechanicalReduction>
    </actuator>
  </transmission>
  <transmission name="elbow_trans">
    <type>transmission_interface/SimpleTransmission</type>
    <joint name="elbow_joint">
      <hardwareInterface>hardware_interface/PositionJointInterface</hardwareInterface>
    </joint>
    <actuator name="elbow_motor">
      <mechanicalReduction>1</mechanicalReduction>
    </actuator>
  </transmission>
  <transmission name="wrist_1_trans">
    <type>transmission_interface/SimpleTransmission</type>
    <joint name="wrist_1_joint">
      <hardwareInterface>hardware_interface/PositionJointInterface</hardwareInterface>
    </joint>
    <actuator name="wrist_1_motor">
      <mechanicalReduction>1</mechanicalReduction>
    </actuator>
  </transmission>
  <transmission name="wrist_2_trans">
    <type>transmission_interface/SimpleTransmission</type>
    <joint name="wrist_2_joint">
      <hardwareInterface>hardware_interface/PositionJointInterface</hardwareInterface>
    </joint>
    <actuator name="wrist_2_motor">
      <mechanicalReduction>1</mechanicalReduction>
    </actuator>
  </transmission>
  <transmission name="wrist_3_trans">
    <type>transmission_interface/SimpleTransmission</type>
    <joint name="wrist_3_joint">
      <hardwareInterface>hardware_interface/PositionJointInterface</hardwareInterface>
    </joint>
    <actuator name="wrist_3_motor">
      <mechanicalReduction>1</mechanicalReduction>
    </actuator>
  </transmission>
  <gazebo reference="shoulder_link">
    <selfCollide>true</selfCollide>
    <gravity>0</gravity>
  </gazebo>
  <gazebo reference="upper_arm_link">
    <selfCollide>true</selfCollide>
    <gravity>0</gravity>
  </gazebo>
  <gazebo reference="forearm_link">
    <selfCollide>true</selfCollide>
    <gravity>0</gravity>
  </gazebo>
  <gazebo reference="wrist_1_link">
    <selfCollide>true</selfCollide>
    <gravity>0</gravity>
  </gazebo>
  <gazebo reference="wrist_3_link">
    <selfCollide>true</selfCollide>
    <gravity>0</gravity>
  </gazebo>
  <gazebo reference="wrist_2_link">
    <selfCollide>true</selfCollide>
    <gravity>0</gravity>
  </gazebo>
  <gazebo reference="ee_link">
    <selfCollide>true</selfCollide>
    <gravity>0</gravity>
  </gazebo>
  <!-- ROS base_link to UR 'Base' Coordinates transform -->
  <link name="base"/>
  <joint name="base_link-base_fixed_joint" type="fixed">
    <!-- NOTE: this rotation is only needed as long as base_link itself is
                 not corrected wrt the real robot (ie: rotated over 180
                 degrees)
      -->
    <origin rpy="0 0 -3.141592653589793" xyz="0 0 0"/>
    <parent link="base_link"/>
    <child link="base"/>
  </joint>
  <!-- Frame coincident with all-zeros TCP on UR controller -->
  <link name="tool0"/>
  <joint name="wrist_3_link-tool0_fixed_joint" type="fixed">
    <origin rpy="-1.5707963267948966 0 0" xyz="0 0.1 0"/>
    <parent link="wrist_3_link"/>
    <child link="tool0"/>
  </joint>
  <link name="world"/>
  <link name="clink_x">
    <visual>
      <geometry>
        <cylinder length="0.005" radius="0.005"/>
      </geometry>
      <origin rpy="0 0 0" xyz="0 0 0"/>
    </visual>
    <collision>
      <geometry>
        <cylinder length="0.00" radius="0.00"/>
      </geometry>
      <origin rpy="0 0 0" xyz="0 0 0"/>
    </collision>
    <inertial>
      <mass value="1"/>
      <origin rpy="0 0 0" xyz="0 0 0"/>
      <!-- <inertia ixx="0.0001" ixy="0.0" ixz="0.0" iyy="0.0001" iyz="0.0" izz="0.0001" /> -->
      <inertia ixx="1" ixy="0.0" ixz="0.0" iyy="1" iyz="0.0" izz="1"/>
    </inertial>
  </link>
  <joint name="robot_tx" type="prismatic">
    <parent link="world"/>
    <child link="clink_x"/>
    <limit effort="1000.0" lower="-5" upper="5" velocity="0.5"/>
    <axis xyz="1 0 0"/>
    <origin xyz="0 0 1.15"/>
  </joint>
  <transmission name="j1">
    <type>transmission_interface/SimpleTransmission</type>
    <joint name="robot_tx">
      <hardwareInterface>hardware_interface/PositionJointInterface</hardwareInterface>
    </joint>
    <actuator name="motor1">
      <hardwareInterface>hardware_interface/PositionJointInterface</hardwareInterface>
      <mechanicalReduction>1</mechanicalReduction>
    </actuator>
  </transmission>
  <link name="clink_y">
    <visual>
      <geometry>
        <cylinder length="0.005" radius="0.005"/>
      </geometry>
      <origin rpy="0 0 0" xyz="0 0 0"/>
    </visual>
    <collision>
      <geometry>
        <cylinder length="0.00" radius="0.00"/>
      </geometry>
      <origin rpy="0 0 0" xyz="0 0 0"/>
    </collision>
    <inertial>
      <mass value="1"/>
      <origin rpy="0 0 0" xyz="0 0 0"/>
      <!-- <inertia ixx="0.0001" ixy="0.0" ixz="0.0" iyy="0.0001" iyz="0.0" izz="0.0001" /> -->
      <inertia ixx="1" ixy="0.0" ixz="0.0" iyy="1" iyz="0.0" izz="1"/>
    </inertial>
  </link>
  <joint name="robot_ty" type="prismatic">
    <parent link="clink_x"/>
    <child link="clink_y"/>
    <limit effort="5000.0" lower="-5" upper="5" velocity="0.5"/>
    <axis xyz="0 1 0"/>
    <origin xyz="0 0 0"/>
  </joint>
  <transmission name="j2">
    <type>transmission_interface/SimpleTransmission</type>
    <joint name="robot_ty">
      <hardwareInterface>hardware_interface/PositionJointInterface</hardwareInterface>
    </joint>
    <actuator name="motor2">
      <hardwareInterface>hardware_interface/PositionJointInterface</hardwareInterface>
      <mechanicalReduction>1</mechanicalReduction>
    </actuator>
  </transmission>
  <joint name="robot_rz" type="continuous">
    <!-- Shouldnt this be rotational?-->
    &gt;
			
    <parent link="clink_y"/>
    <child link="base_link"/>
    <limit effort="1000.0" lower="-3.14" upper="3.14" velocity="0.2"/>
    <axis xyz="0 0 1"/>
    <origin rpy="0 0 0" xyz="0 0 0"/>
  </joint>
  <transmission name="j3">
    <type>transmission_interface/SimpleTransmission</type>
    <joint name="robot_rz">
      <hardwareInterface>hardware_interface/PositionJointInterface</hardwareInterface>
    </joint>
    <actuator name="motor3">
      <hardwareInterface>hardware_interface/PositionJointInterface</hardwareInterface>
      <mechanicalReduction>1</mechanicalReduction>
    </actuator>
  </transmission>
  <!-- Base link is the center of the robot's bottom plate -->
  <link name="base_link_husky">
    <visual>
      <origin rpy="0 0 0" xyz="0 0 0"/>
      <geometry>
        <mesh filename="package://mobile_manipulator_moveit_config/meshes/base_link.dae"/>
      </geometry>
    </visual>
    <collision>
      <origin rpy="0 0 0" xyz="0 0 0.061875"/>
      <geometry>
        <box size="0.9874 0.5709 0.12375"/>
      </geometry>
    </collision>
    <collision>
      <origin rpy="0 0 0" xyz="0 0 0.17562499999999998"/>
      <geometry>
        <box size="0.7899200000000001 0.5709 0.10375"/>
      </geometry>
    </collision>
    <inertial>
      <mass value="50"/>
      <origin xyz="0.0 0.0 0.0"/>
      <!-- <inertia ixx="50" ixy="0" ixz="0" iyy="50" iyz="0" izz="50" /> -->
      <inertia ixx="0.6022" ixy="0.0" ixz="0.0" iyy="1.7386" iyz="0.0" izz="2.0296"/>
    </inertial>
  </link>
  <!-- Inertial link stores the robot's inertial information -->
  <!-- <link name="inertial_link">
	    <inertial>
	      <mass value="46.034" />
	      <origin xyz="-0.00065 -0.085 0.062" />
	      <inertia ixx="0.6022" ixy="-0.02364" ixz="-0.1197" iyy="1.7386" iyz="-0.001544" izz="2.0296" />
	    </inertial>
	  </link>

	  <joint name="inertial_joint" type="fixed">
	    <origin xyz="0 0 0" rpy="0 0 0" />
	    <parent link="base_link_husky" />
	    <child link="inertial_link" />
	  </joint> -->
  <joint name="jbox" type="fixed">
    <parent link="base_link"/>
    <child link="base_link_husky"/>
    <axis xyz="0 0 1"/>
    <origin rpy="0 0 0" xyz="0 0 -0.9520799999999999"/>
  </joint>
  <!-- Base footprint is on the ground under the robot -->
  <link name="base_footprint"/>
  <joint name="base_footprint_joint" type="fixed">
    <origin rpy="0 0 0" xyz="0 0 -0.13228"/>
    <parent link="base_link_husky"/>
    <child link="base_footprint"/>
  </joint>
  <link name="front_left_wheel_link">
    <inertial>
      <mass value="2.637"/>
      <origin xyz="0 0 0"/>
      <inertia ixx="0.02467" ixy="0" ixz="0" iyy="0.04411" iyz="0" izz="0.02467"/>
    </inertial>
    <visual>
      <origin rpy="0 0 0" xyz="0 0 0"/>
      <geometry>
        <mesh filename="package://mobile_manipulator_moveit_config/meshes/wheel.dae"/>
      </geometry>
    </visual>
    <collision>
      <origin rpy="1.570795 0 0" xyz="0 0 0"/>
      <geometry>
        <cylinder length="0.1143" radius="0.1651"/>
      </geometry>
    </collision>
  </link>
  <gazebo reference="front_left_wheel_link">
    <mu1 value="1.0"/>
    <mu2 value="1.0"/>
    <kp value="10000000.0"/>
    <kd value="1.0"/>
    <fdir1 value="1 0 0"/>
  </gazebo>
  <joint name="front_left_wheel" type="fixed">
    <parent link="base_link_husky"/>
    <child link="front_left_wheel_link"/>
    <origin rpy="0 0 0" xyz="0.256 0.2854 0.03282"/>
    <axis rpy="0 0 0" xyz="0 1 0"/>
  </joint>
  <link name="front_right_wheel_link">
    <inertial>
      <mass value="2.637"/>
      <origin xyz="0 0 0"/>
      <inertia ixx="0.02467" ixy="0" ixz="0" iyy="0.04411" iyz="0" izz="0.02467"/>
    </inertial>
    <visual>
      <origin rpy="0 0 0" xyz="0 0 0"/>
      <geometry>
        <mesh filename="package://mobile_manipulator_moveit_config/meshes/wheel.dae"/>
      </geometry>
    </visual>
    <collision>
      <origin rpy="1.570795 0 0" xyz="0 0 0"/>
      <geometry>
        <cylinder length="0.1143" radius="0.1651"/>
      </geometry>
    </collision>
  </link>
  <gazebo reference="front_right_wheel_link">
    <mu1 value="1.0"/>
    <mu2 value="1.0"/>
    <kp value="10000000.0"/>
    <kd value="1.0"/>
    <fdir1 value="1 0 0"/>
  </gazebo>
  <joint name="front_right_wheel" type="fixed">
    <parent link="base_link_husky"/>
    <child link="front_right_wheel_link"/>
    <origin rpy="0 0 0" xyz="0.256 -0.2854 0.03282"/>
    <axis rpy="0 0 0" xyz="0 1 0"/>
  </joint>
  <link name="rear_left_wheel_link">
    <inertial>
      <mass value="2.637"/>
      <origin xyz="0 0 0"/>
      <inertia ixx="0.02467" ixy="0" ixz="0" iyy="0.04411" iyz="0" izz="0.02467"/>
    </inertial>
    <visual>
      <origin rpy="0 0 0" xyz="0 0 0"/>
      <geometry>
        <mesh filename="package://mobile_manipulator_moveit_config/meshes/wheel.dae"/>
      </geometry>
    </visual>
    <collision>
      <origin rpy="1.570795 0 0" xyz="0 0 0"/>
      <geometry>
        <cylinder length="0.1143" radius="0.1651"/>
      </geometry>
    </collision>
  </link>
  <gazebo reference="rear_left_wheel_link">
    <mu1 value="1.0"/>
    <mu2 value="1.0"/>
    <kp value="10000000.0"/>
    <kd value="1.0"/>
    <fdir1 value="1 0 0"/>
  </gazebo>
  <joint name="rear_left_wheel" type="fixed">
    <parent link="base_link_husky"/>
    <child link="rear_left_wheel_link"/>
    <origin rpy="0 0 0" xyz="-0.256 0.2854 0.03282"/>
    <axis rpy="0 0 0" xyz="0 1 0"/>
  </joint>
  <link name="rear_right_wheel_link">
    <inertial>
      <mass value="2.637"/>
      <origin xyz="0 0 0"/>
      <inertia ixx="0.02467" ixy="0" ixz="0" iyy="0.04411" iyz="0" izz="0.02467"/>
    </inertial>
    <visual>
      <origin rpy="0 0 0" xyz="0 0 0"/>
      <geometry>
        <mesh filename="package://mobile_manipulator_moveit_config/meshes/wheel.dae"/>
      </geometry>
    </visual>
    <collision>
      <origin rpy="1.570795 0 0" xyz="0 0 0"/>
      <geometry>
        <cylinder length="0.1143" radius="0.1651"/>
      </geometry>
    </collision>
  </link>
  <gazebo reference="rear_right_wheel_link">
    <mu1 value="1.0"/>
    <mu2 value="1.0"/>
    <kp value="10000000.0"/>
    <kd value="1.0"/>
    <fdir1 value="1 0 0"/>
  </gazebo>
  <joint name="rear_right_wheel" type="fixed">
    <parent link="base_link_husky"/>
    <child link="rear_right_wheel_link"/>
    <origin rpy="0 0 0" xyz="-0.256 -0.2854 0.03282"/>
    <axis rpy="0 0 0" xyz="0 1 0"/>
  </joint>
  <!-- Spawn Husky chassis -->
  <link name="top_chassis_link">
    <visual>
      <origin rpy="0 0 0" xyz="0 0 0"/>
      <geometry>
        <mesh filename="package://mobile_manipulator_moveit_config/meshes/top_chassis.dae"/>
      </geometry>
    </visual>
    <collision>
      <origin rpy="0 0 0" xyz="0 0 0"/>
      <geometry>
        <mesh filename="package://mobile_manipulator_moveit_config/meshes/top_chassis.dae"/>
      </geometry>
    </collision>
  </link>
  <!-- Attach chassis to the robot -->
  <joint name="top_chassis_joint" type="fixed">
    <parent link="base_link_husky"/>
    <child link="top_chassis_link"/>
  </joint>
  <!-- Spawn user rails -->
  <link name="user_rail_link">
    <visual>
      <geometry>
        <mesh filename="package://mobile_manipulator_moveit_config/meshes/user_rail.dae"/>
      </geometry>
    </visual>
    <collision>
      <geometry>
        <mesh filename="package://mobile_manipulator_moveit_config/meshes/user_rail.dae"/>
      </geometry>
    </collision>
  </link>
  <!-- Attach user rails to base link -->
  <joint name="user_rail" type="fixed">
    <origin rpy="0 0 0" xyz="0.272 0 0.245"/>
    <parent link="base_link_husky"/>
    <child link="user_rail_link"/>
  </joint>
  <!-- Spawn front bumper link -->
  <link name="front_bumper_link">
    <visual>
      <geometry>
        <mesh filename="package://mobile_manipulator_moveit_config/meshes/bumper.dae"/>
      </geometry>
    </visual>
    <collision>
      <geometry>
        <mesh filename="package://mobile_manipulator_moveit_config/meshes/bumper.dae"/>
      </geometry>
    </collision>
  </link>
  <!-- Attach front bumper -->
  <joint name="front_bumper" type="fixed">
    <origin rpy="0 0 0" xyz="0.48 0 0.091"/>
    <parent link="base_link_husky"/>
    <child link="front_bumper_link"/>
  </joint>
  <!-- Spawn rear bumper link -->
  <link name="rear_bumper_link">
    <visual>
      <geometry>
        <mesh filename="package://mobile_manipulator_moveit_config/meshes/bumper.dae"/>
      </geometry>
    </visual>
    <collision>
      <geometry>
        <mesh filename="package://mobile_manipulator_moveit_config/meshes/bumper.dae"/>
      </geometry>
    </collision>
  </link>
  <!-- Attach rear bumper -->
  <joint name="rear_bumper" type="fixed">
    <origin rpy="0 0 3.14159" xyz="-0.48 0 0.091"/>
    <parent link="base_link_husky"/>
    <child link="rear_bumper_link"/>
  </joint>
  <link name="top_plate_link">
    <visual>
      <origin rpy="0 0 0" xyz="0 0 0"/>
      <geometry>
        <mesh filename="package://mobile_manipulator_moveit_config/meshes/top_plate.dae"/>
      </geometry>
    </visual>
    <collision>
      <origin rpy="0 0 0" xyz="0 0 0"/>
      <geometry>
        <mesh filename="package://mobile_manipulator_moveit_config/meshes/top_plate.stl"/>
      </geometry>
    </collision>
  </link>
  <!-- Attach top plate -->
  <joint name="top_plate_joint" type="fixed">
    <parent link="base_link_husky"/>
    <child link="top_plate_link"/>
    <origin rpy="0 0 0" xyz="0.0812 0 0.245"/>
  </joint>
  <!-- Top plate front link -->
  <joint name="top_plate_front_joint" type="fixed">
    <parent link="top_plate_link"/>
    <child link="top_plate_front_link"/>
    <origin rpy="0 0 0" xyz="0.36367 0 0.00639"/>
  </joint>
  <!-- Top plate rear link-->
  <joint name="top_plate_rear_joint" type="fixed">
    <parent link="top_plate_link"/>
    <child link="top_plate_rear_link"/>
    <origin rpy="0 0 0" xyz="-0.36633 0 0.00639"/>
  </joint>
  <link name="top_plate_front_link"/>
  <link name="top_plate_rear_link"/>
  <link name="EEF">
    <visual>
      <geometry>
        <box size="0.05 0.05 0.05"/>
      </geometry>
      <origin rpy="0 0 0" xyz="0.05 0.0 0.0"/>
      <material name="white"/>
    </visual>
    <collision>
      <geometry>
        <box size="0.05 0.05 0.05"/>
      </geometry>
      <origin rpy="0 0 0" xyz="0.05 0.0 0.0"/>
    </collision>
  </link>
  <joint name="jeef" type="fixed">
    <parent link="ee_link"/>
    <child link="EEF"/>
    <axis xyz="0 0 1"/>
    <origin rpy="0 0 0" xyz="0 0 0"/>
  </joint>
  <link name="control_box">
    <visual>
      <geometry>
        <box size="0.52 0.59 0.68"/>
      </geometry>
      <material name="white"/>
    </visual>
    <collision>
      <geometry>
        <box size="0.52 0.59 0.68"/>
      </geometry>
    </collision>
  </link>
  <joint name="jcb" type="fixed">
    <parent link="base_link"/>
    <child link="control_box"/>
    <axis xyz="0 0 1"/>
    <origin rpy="0 0 0" xyz="0 0 -0.35"/>
  </joint>
  <!-- Camera mounting point (the threaded screw hole in the bottom) -->
  <link name="zed2i_front_base_link"/>
  <joint name="zed2i_front_base_joint" type="fixed">
    <parent link="control_box"/>
    <child link="zed2i_front_base_link"/>
    <origin rpy="0.0 0.0 0.0" xyz="0.26 0 0.34 "/>
  </joint>
  <!-- Camera Center -->
  <link name="zed2i_front_camera_center">
    <visual>
      <origin rpy="0 0 0" xyz="-0.01 0 0"/>
      <geometry>
        <mesh filename="package://mobile_manipulator_moveit_config/meshes/zed2i.stl"/>
      </geometry>
      <material name="zed2i_mat"/>
    </visual>
    <collision>
      <geometry>
        <mesh filename="package://mobile_manipulator_moveit_config/meshes/zed2i.stl"/>
      </geometry>
    </collision>
  </link>
  <joint name="zed2i_front_camera_center_joint" type="fixed">
    <parent link="zed2i_front_base_link"/>
    <child link="zed2i_front_camera_center"/>
    <origin rpy="0 0.0 0" xyz="0 0 0.015"/>
  </joint>
  <!-- Left Camera -->
  <link name="zed2i_front_left_camera_frame"/>
  <joint name="zed2i_front_left_camera_joint" type="fixed">
    <parent link="zed2i_front_camera_center"/>
    <child link="zed2i_front_left_camera_frame"/>
    <origin rpy="0 0 0" xyz="0.01 0.06 0"/>
  </joint>
  <link name="zed2i_front_left_camera_optical_frame"/>
  <joint name="zed2i_front_left_camera_optical_joint" type="fixed">
    <origin rpy="-1.570795 0.0 -1.570795" xyz="-0.01 0 0"/>
    <parent link="zed2i_front_left_camera_frame"/>
    <child link="zed2i_front_left_camera_optical_frame"/>
  </joint>
  <!-- Right Camera -->
  <link name="zed2i_front_right_camera_frame"/>
  <joint name="zed2i_front_right_camera_joint" type="fixed">
    <parent link="zed2i_front_camera_center"/>
    <child link="zed2i_front_right_camera_frame"/>
    <origin rpy="0 0 0" xyz="0.01 -0.06 0"/>
  </joint>
  <link name="zed2i_front_right_camera_optical_frame"/>
  <joint name="zed2i_front_right_camera_optical_joint" type="fixed">
    <origin rpy="-1.570795 0.0 -1.570795" xyz="-0.01 0 0"/>
    <parent link="zed2i_front_right_camera_frame"/>
    <child link="zed2i_front_right_camera_optical_frame"/>
  </joint>
  <link name="zed2i_front_mag_link"/>
  <joint name="zed2i_front_mag_joint" type="fixed">
    <parent link="zed2i_front_camera_center"/>
    <child link="zed2i_front_mag_link"/>
    <origin rpy="0 0 0" xyz="0 0 0"/>
  </joint>
  <link name="zed2i_front_baro_link"/>
  <joint name="zed2i_front_baro_joint" type="fixed">
    <parent link="zed2i_front_camera_center"/>
    <child link="zed2i_front_baro_link"/>
    <origin rpy="0 0 0" xyz="0 0 0"/>
  </joint>
  <link name="zed2i_front_imu_link"/>
  <joint name="zed2i_front_imu_joint" type="fixed">
    <parent link="zed2i_front_camera_center"/>
    <child link="zed2i_front_imu_link"/>
    <origin rpy="0 0 0" xyz="0 0 0"/>
  </joint>
  <link name="zed2i_front_temp_left_link"/>
  <joint name="zed2i_front_temp_left_joint" type="fixed">
    <parent link="zed2i_front_left_camera_frame"/>
    <child link="zed2i_front_temp_left_link"/>
    <origin rpy="0 0 0" xyz="0 0 0"/>
  </joint>
  <link name="zed2i_front_temp_right_link"/>
  <joint name="zed2i_front_temp_right_joint" type="fixed">
    <parent link="zed2i_front_right_camera_frame"/>
    <child link="zed2i_front_temp_right_link"/>
    <origin rpy="0 0 0" xyz="0 0 0"/>
  </joint>
  <joint name="zed2i_front_imu_base_mount_joint" type="fixed">
    <origin rpy="0.0 0.0 0.0" xyz="0.0 0.0 0.0"/>
    <parent link="zed2i_front_imu_link"/>
    <child link="zed2i_front_imu"/>
  </joint>
  <link name="zed2i_front_imu">
    </link>
  <gazebo reference="zed2i_front_imu">
    <gravity>true</gravity>
    <sensor name="imu_sensor" type="imu">
      <always_on>true</always_on>
      <update_rate>100</update_rate>
      <visualize>true</visualize>
      <topic>zed2i_front/imu</topic>
      <plugin filename="libgazebo_ros_imu_sensor.so" name="imu_plugin">
        <robotNamespace>MobileManipulator</robotNamespace>
        <topicName>zed2i_front/imu</topicName>
        <bodyName>zed2i_front_imu</bodyName>
        <updateRateHZ>400</updateRateHZ>
        <gaussianNoise>0.0</gaussianNoise>
        <xyzOffset>0 0 0</xyzOffset>
        <rpyOffset>0 0 0</rpyOffset>
        <frameName>zed2i_front_imu</frameName>
        <initialOrientationAsReference>false</initialOrientationAsReference>
      </plugin>
      <pose>0 0 0 0 0 0</pose>
    </sensor>
  </gazebo>
  <!--Reference for ZED2i 2.1mm https://www.stereolabs.com/assets/datasheets/zed-2i-datasheet-feb2022.pdf -->
  <!--Left Camera -->
  <gazebo reference="zed2i_front_left_camera_frame">
    <sensor name="zed2i_front" type="camera">
      <update_rate>30.0</update_rate>
      <!--Supports 15, 30, 60, 100 -->
      <camera name="left_camera">
        <horizontal_fov>1.74533</horizontal_fov>
        <!--100°-->
        <vertical_fov>1.22173</vertical_fov>
        <!--70°-->
        <diagonal_fov>2.09439</diagonal_fov>
        <!--120°-->
        <image>
          <width>1920</width>
          <!--Supports 1280x720, 1920x1080, 2208x1242, 662x376-->
          <height>1080</height>
          <format>R8G8B8</format>
          <!--R8G8B8 -->
        </image>
        <clip>
          <near>0.005</near>
          <far>10.0</far>
        </clip>
        <noise>
          <type>gaussian</type>
          <mean>0.01</mean>
          <stddev>0.007</stddev>
        </noise>
      </camera>
      <plugin filename="libgazebo_ros_camera.so" name="camera_controller">
        <robotNamespace>MobileManipulator</robotNamespace>
        <alwaysOn>true</alwaysOn>
        <updateRate>0.0</updateRate>
        <cameraName>zed2i_front_left_camera</cameraName>
        <imageTopicName>image_left_raw</imageTopicName>
        <cameraInfoTopicName>zed2i_front_left_camera_info</cameraInfoTopicName>
        <frameName>zed2i_front_left_camera_frame</frameName>
        <hackBaseline>0.07</hackBaseline>
        <distortionK1>0.0</distortionK1>
        <distortionK2>0.0</distortionK2>
        <distortionK3>0.0</distortionK3>
        <distortionT1>0.0</distortionT1>
        <distortionT2>0.0</distortionT2>
      </plugin>
    </sensor>
  </gazebo>
  <!--Right Camera -->
  <gazebo reference="zed2i_front_right_camera_frame">
    <sensor name="zed2i_front" type="camera">
      <update_rate>30.0</update_rate>
      <!--Supports 15, 30, 60, 100 -->
      <camera name="right_camera">
        <horizontal_fov>1.74533</horizontal_fov>
        <!--100°-->
        <vertical_fov>1.22173</vertical_fov>
        <!--70°-->
        <diagonal_fov>2.09439</diagonal_fov>
        <!--120°-->
        <image>
          <width>1920</width>
          <!--Supports 1280x720, 1920x1080, 2208x1242, 662x376-->
          <height>1080</height>
          <format>R8G8B8</format>
          <!--R8G8B8 -->
        </image>
        <clip>
          <near>0.005</near>
          <far>10.0</far>
        </clip>
        <noise>
          <type>gaussian</type>
          <mean>0.01</mean>
          <stddev>0.007</stddev>
        </noise>
      </camera>
      <plugin filename="libgazebo_ros_camera.so" name="camera_controller">
        <alwaysOn>true</alwaysOn>
        <robotNamespace>MobileManipulator</robotNamespace>
        <updateRate>0.0</updateRate>
        <cameraName>zed2i_front_right_camera</cameraName>
        <imageTopicName>image_right_raw</imageTopicName>
        <cameraInfoTopicName>zed2i_front_right_camera_info</cameraInfoTopicName>
        <frameName>zed2i_front_right_camera_frame</frameName>
        <hackBaseline>0.07</hackBaseline>
        <distortionK1>0.0</distortionK1>
        <distortionK2>0.0</distortionK2>
        <distortionK3>0.0</distortionK3>
        <distortionT1>0.0</distortionT1>
        <distortionT2>0.0</distortionT2>
      </plugin>
    </sensor>
  </gazebo>
  <gazebo reference="zed2i_front_camera_center">
    <sensor name="zed2i_front" type="ray">
      <pose>0 0 0 0 0 0</pose>
      <always_on>true</always_on>
      <visualize>false</visualize>
      <update_rate>10</update_rate>
      <ray>
        <scan>
          <horizontal>
            <samples>50</samples>
            <resolution>0.1</resolution>
            <min_angle>-0.959931</min_angle>
            <max_angle>0.959931</max_angle>
          </horizontal>
          <vertical>
            <samples>50</samples>
            <resolution>0.1</resolution>
            <min_angle>-0.610865</min_angle>
            <max_angle>0.610865</max_angle>
          </vertical>
        </scan>
        <range>
          <min>0.3</min>
          <max>20</max>
          <resolution>0.015000</resolution>
        </range>
        <noise>
          <type>gaussian</type>
          <mean>0.0</mean>
          <stddev>0.0</stddev>
        </noise>
      </ray>
      <plugin filename="libgazebo_ros_velodyne_laser.so" name="gazebo_ros_laser_controller">
        <topicName>zed2i_front_depth</topicName>
        <frameName>zed2i_front_camera_center</frameName>
        <organize_cloud>false</organize_cloud>
        <min_range>0.3</min_range>
        <max_range>20</max_range>
        <gaussianNoise>0.005</gaussianNoise>
      </plugin>
    </sensor>
  </gazebo>
  <!-- Camera mounting point (the threaded screw hole in the bottom) -->
  <link name="zed2i_back_base_link"/>
  <joint name="zed2i_back_base_joint" type="fixed">
    <parent link="control_box"/>
    <child link="zed2i_back_base_link"/>
    <origin rpy="0.0 0.0 -3.141592653589793" xyz="-0.26  0 0.34 "/>
  </joint>
  <!-- Camera Center -->
  <link name="zed2i_back_camera_center">
    <visual>
      <origin rpy="0 0 0" xyz="-0.01 0 0"/>
      <geometry>
        <mesh filename="package://mobile_manipulator_moveit_config/meshes/zed2i.stl"/>
      </geometry>
      <material name="zed2i_mat"/>
    </visual>
    <collision>
      <geometry>
        <mesh filename="package://mobile_manipulator_moveit_config/meshes/zed2i.stl"/>
      </geometry>
    </collision>
  </link>
  <joint name="zed2i_back_camera_center_joint" type="fixed">
    <parent link="zed2i_back_base_link"/>
    <child link="zed2i_back_camera_center"/>
    <origin rpy="0 0.0 0" xyz="0 0 0.015"/>
  </joint>
  <!-- Left Camera -->
  <link name="zed2i_back_left_camera_frame"/>
  <joint name="zed2i_back_left_camera_joint" type="fixed">
    <parent link="zed2i_back_camera_center"/>
    <child link="zed2i_back_left_camera_frame"/>
    <origin rpy="0 0 0" xyz="0.01 0.06 0"/>
  </joint>
  <link name="zed2i_back_left_camera_optical_frame"/>
  <joint name="zed2i_back_left_camera_optical_joint" type="fixed">
    <origin rpy="-1.570795 0.0 -1.570795" xyz="-0.01 0 0"/>
    <parent link="zed2i_back_left_camera_frame"/>
    <child link="zed2i_back_left_camera_optical_frame"/>
  </joint>
  <!-- Right Camera -->
  <link name="zed2i_back_right_camera_frame"/>
  <joint name="zed2i_back_right_camera_joint" type="fixed">
    <parent link="zed2i_back_camera_center"/>
    <child link="zed2i_back_right_camera_frame"/>
    <origin rpy="0 0 0" xyz="0.01 -0.06 0"/>
  </joint>
  <link name="zed2i_back_right_camera_optical_frame"/>
  <joint name="zed2i_back_right_camera_optical_joint" type="fixed">
    <origin rpy="-1.570795 0.0 -1.570795" xyz="-0.01 0 0"/>
    <parent link="zed2i_back_right_camera_frame"/>
    <child link="zed2i_back_right_camera_optical_frame"/>
  </joint>
  <link name="zed2i_back_mag_link"/>
  <joint name="zed2i_back_mag_joint" type="fixed">
    <parent link="zed2i_back_camera_center"/>
    <child link="zed2i_back_mag_link"/>
    <origin rpy="0 0 0" xyz="0 0 0"/>
  </joint>
  <link name="zed2i_back_baro_link"/>
  <joint name="zed2i_back_baro_joint" type="fixed">
    <parent link="zed2i_back_camera_center"/>
    <child link="zed2i_back_baro_link"/>
    <origin rpy="0 0 0" xyz="0 0 0"/>
  </joint>
  <link name="zed2i_back_imu_link"/>
  <joint name="zed2i_back_imu_joint" type="fixed">
    <parent link="zed2i_back_camera_center"/>
    <child link="zed2i_back_imu_link"/>
    <origin rpy="0 0 0" xyz="0 0 0"/>
  </joint>
  <link name="zed2i_back_temp_left_link"/>
  <joint name="zed2i_back_temp_left_joint" type="fixed">
    <parent link="zed2i_back_left_camera_frame"/>
    <child link="zed2i_back_temp_left_link"/>
    <origin rpy="0 0 0" xyz="0 0 0"/>
  </joint>
  <link name="zed2i_back_temp_right_link"/>
  <joint name="zed2i_back_temp_right_joint" type="fixed">
    <parent link="zed2i_back_right_camera_frame"/>
    <child link="zed2i_back_temp_right_link"/>
    <origin rpy="0 0 0" xyz="0 0 0"/>
  </joint>
  <joint name="zed2i_back_imu_base_mount_joint" type="fixed">
    <origin rpy="0.0 0.0 0.0" xyz="0.0 0.0 0.0"/>
    <parent link="zed2i_back_imu_link"/>
    <child link="zed2i_back_imu"/>
  </joint>
  <link name="zed2i_back_imu">
    </link>
  <gazebo reference="zed2i_back_imu">
    <gravity>true</gravity>
    <sensor name="imu_sensor" type="imu">
      <always_on>true</always_on>
      <update_rate>100</update_rate>
      <visualize>true</visualize>
      <topic>zed2i_back/imu</topic>
      <plugin filename="libgazebo_ros_imu_sensor.so" name="imu_plugin">
        <robotNamespace>MobileManipulator</robotNamespace>
        <topicName>zed2i_back/imu</topicName>
        <bodyName>zed2i_back_imu</bodyName>
        <updateRateHZ>400</updateRateHZ>
        <gaussianNoise>0.0</gaussianNoise>
        <xyzOffset>0 0 0</xyzOffset>
        <rpyOffset>0 0 0</rpyOffset>
        <frameName>zed2i_back_imu</frameName>
        <initialOrientationAsReference>false</initialOrientationAsReference>
      </plugin>
      <pose>0 0 0 0 0 0</pose>
    </sensor>
  </gazebo>
  <!--Reference for ZED2i 2.1mm https://www.stereolabs.com/assets/datasheets/zed-2i-datasheet-feb2022.pdf -->
  <!--Left Camera -->
  <gazebo reference="zed2i_back_left_camera_frame">
    <sensor name="zed2i_back" type="camera">
      <update_rate>30.0</update_rate>
      <!--Supports 15, 30, 60, 100 -->
      <camera name="left_camera">
        <horizontal_fov>1.74533</horizontal_fov>
        <!--100°-->
        <vertical_fov>1.22173</vertical_fov>
        <!--70°-->
        <diagonal_fov>2.09439</diagonal_fov>
        <!--120°-->
        <image>
          <width>1920</width>
          <!--Supports 1280x720, 1920x1080, 2208x1242, 662x376-->
          <height>1080</height>
          <format>R8G8B8</format>
          <!--R8G8B8 -->
        </image>
        <clip>
          <near>0.005</near>
          <far>10.0</far>
        </clip>
        <noise>
          <type>gaussian</type>
          <mean>0.01</mean>
          <stddev>0.007</stddev>
        </noise>
      </camera>
      <plugin filename="libgazebo_ros_camera.so" name="camera_controller">
        <robotNamespace>MobileManipulator</robotNamespace>
        <alwaysOn>true</alwaysOn>
        <updateRate>0.0</updateRate>
        <cameraName>zed2i_back_left_camera</cameraName>
        <imageTopicName>image_left_raw</imageTopicName>
        <cameraInfoTopicName>zed2i_back_left_camera_info</cameraInfoTopicName>
        <frameName>zed2i_back_left_camera_frame</frameName>
        <hackBaseline>0.07</hackBaseline>
        <distortionK1>0.0</distortionK1>
        <distortionK2>0.0</distortionK2>
        <distortionK3>0.0</distortionK3>
        <distortionT1>0.0</distortionT1>
        <distortionT2>0.0</distortionT2>
      </plugin>
    </sensor>
  </gazebo>
  <!--Right Camera -->
  <gazebo reference="zed2i_back_right_camera_frame">
    <sensor name="zed2i_back" type="camera">
      <update_rate>30.0</update_rate>
      <!--Supports 15, 30, 60, 100 -->
      <camera name="right_camera">
        <horizontal_fov>1.74533</horizontal_fov>
        <!--100°-->
        <vertical_fov>1.22173</vertical_fov>
        <!--70°-->
        <diagonal_fov>2.09439</diagonal_fov>
        <!--120°-->
        <image>
          <width>1920</width>
          <!--Supports 1280x720, 1920x1080, 2208x1242, 662x376-->
          <height>1080</height>
          <format>R8G8B8</format>
          <!--R8G8B8 -->
        </image>
        <clip>
          <near>0.005</near>
          <far>10.0</far>
        </clip>
        <noise>
          <type>gaussian</type>
          <mean>0.01</mean>
          <stddev>0.007</stddev>
        </noise>
      </camera>
      <plugin filename="libgazebo_ros_camera.so" name="camera_controller">
        <alwaysOn>true</alwaysOn>
        <robotNamespace>MobileManipulator</robotNamespace>
        <updateRate>0.0</updateRate>
        <cameraName>zed2i_back_right_camera</cameraName>
        <imageTopicName>image_right_raw</imageTopicName>
        <cameraInfoTopicName>zed2i_back_right_camera_info</cameraInfoTopicName>
        <frameName>zed2i_back_right_camera_frame</frameName>
        <hackBaseline>0.07</hackBaseline>
        <distortionK1>0.0</distortionK1>
        <distortionK2>0.0</distortionK2>
        <distortionK3>0.0</distortionK3>
        <distortionT1>0.0</distortionT1>
        <distortionT2>0.0</distortionT2>
      </plugin>
    </sensor>
  </gazebo>
  <gazebo reference="zed2i_back_camera_center">
    <sensor name="zed2i_back" type="ray">
      <pose>0 0 0 0 0 0</pose>
      <always_on>true</always_on>
      <visualize>false</visualize>
      <update_rate>10</update_rate>
      <ray>
        <scan>
          <horizontal>
            <samples>50</samples>
            <resolution>0.1</resolution>
            <min_angle>-0.959931</min_angle>
            <max_angle>0.959931</max_angle>
          </horizontal>
          <vertical>
            <samples>50</samples>
            <resolution>0.1</resolution>
            <min_angle>-0.610865</min_angle>
            <max_angle>0.610865</max_angle>
          </vertical>
        </scan>
        <range>
          <min>0.3</min>
          <max>20</max>
          <resolution>0.015000</resolution>
        </range>
        <noise>
          <type>gaussian</type>
          <mean>0.0</mean>
          <stddev>0.0</stddev>
        </noise>
      </ray>
      <plugin filename="libgazebo_ros_velodyne_laser.so" name="gazebo_ros_laser_controller">
        <topicName>zed2i_back_depth</topicName>
        <frameName>zed2i_back_camera_center</frameName>
        <organize_cloud>false</organize_cloud>
        <min_range>0.3</min_range>
        <max_range>20</max_range>
        <gaussianNoise>0.005</gaussianNoise>
      </plugin>
    </sensor>
  </gazebo>
  <joint name="rs0_frame_base_mount_joint" type="fixed">
    <origin rpy="0.0 0.534 0.0" xyz="0.35 0.0 0.3"/>
    <parent link="base_link_husky"/>
    <child link="rs0_frame"/>
  </joint>
  <link name="rs0_frame">
    <inertial>
      <mass value="1.0"/>
      <origin xyz="0 0 0.07212"/>
      <inertia ixx="0.002188947025" ixy="0" ixz="0" iyy="0.002188947025" iyz="0" izz="0.00091036445"/>
    </inertial>
    <visual>
      <geometry>
        <mesh filename="package://mobile_manipulator_moveit_config/meshes/robosense_rsbpearl.STL"/>
      </geometry>
      <material name="purple">
        <color rgba="0.5 0 0.5 0.5"/>
      </material>
    </visual>
    <collision>
      <geometry>
        <cylinder length="0.0" radius="0.0"/>
      </geometry>
    </collision>
    <!--collision>
        <origin rpy="0 0 0" xyz="0 0 0.07212"/>
        <geometry>
          <cylinder radius="0.04267" length="0.14424"/>
        </geometry>
      </collision> -->
  </link>
  <!-- Gazebo requires the velodyne_gazebo_plugins package -->
  <gazebo reference="rs0_frame">
    <sensor name="rs0_frame" type="ray">
      <pose>0 0 0 0 0 0</pose>
      <visualize>false</visualize>
      <update_rate>10</update_rate>
      <ray>
        <scan>
          <horizontal>
            <samples>220</samples>
            <resolution>1</resolution>
            <min_angle>-3.14159</min_angle>
            <max_angle>3.14159</max_angle>
          </horizontal>
          <vertical>
            <samples>32</samples>
            <resolution>1</resolution>
            <min_angle>0.0</min_angle>
            <max_angle> 1.570795</max_angle>
          </vertical>
        </scan>
        <range>
          <min>0.05</min>
          <max>131.0</max>
          <resolution>0.001</resolution>
        </range>
        <noise>
          <type>gaussian</type>
          <mean>0.0</mean>
          <stddev>0.0</stddev>
        </noise>
      </ray>
      <plugin filename="libgazebo_ros_velodyne_laser.so" name="gazebo_ros_laser_controller">
        <topicName>/rs0_points</topicName>
        <frameName>rs0_frame</frameName>
        <organize_cloud>False</organize_cloud>
        <min_range>0.05</min_range>
        <max_range>130.0</max_range>
        <gaussianNoise>0.008</gaussianNoise>
      </plugin>
    </sensor>
  </gazebo>
  <joint name="rs1_frame_base_mount_joint" type="fixed">
    <origin rpy="0.0 0.534 3.14159" xyz="-0.35 0.0 0.3"/>
    <parent link="base_link_husky"/>
    <child link="rs1_frame"/>
  </joint>
  <link name="rs1_frame">
    <inertial>
      <mass value="1.0"/>
      <origin xyz="0 0 0.07212"/>
      <inertia ixx="0.002188947025" ixy="0" ixz="0" iyy="0.002188947025" iyz="0" izz="0.00091036445"/>
    </inertial>
    <visual>
      <geometry>
        <mesh filename="package://mobile_manipulator_moveit_config/meshes/robosense_rsbpearl.STL"/>
      </geometry>
      <material name="purple">
        <color rgba="0.5 0 0.5 0.5"/>
      </material>
    </visual>
    <collision>
      <geometry>
        <cylinder length="0.0" radius="0.0"/>
      </geometry>
    </collision>
    <!--collision>
        <origin rpy="0 0 0" xyz="0 0 0.07212"/>
        <geometry>
          <cylinder radius="0.04267" length="0.14424"/>
        </geometry>
      </collision> -->
  </link>
  <!-- Gazebo requires the velodyne_gazebo_plugins package -->
  <gazebo reference="rs1_frame">
    <sensor name="rs1_frame" type="ray">
      <pose>0 0 0 0 0 0</pose>
      <visualize>false</visualize>
      <update_rate>10</update_rate>
      <ray>
        <scan>
          <horizontal>
            <samples>220</samples>
            <resolution>1</resolution>
            <min_angle>-3.14159</min_angle>
            <max_angle>3.14159</max_angle>
          </horizontal>
          <vertical>
            <samples>32</samples>
            <resolution>1</resolution>
            <min_angle>0.0</min_angle>
            <max_angle> 1.570795</max_angle>
          </vertical>
        </scan>
        <range>
          <min>0.05</min>
          <max>131.0</max>
          <resolution>0.001</resolution>
        </range>
        <noise>
          <type>gaussian</type>
          <mean>0.0</mean>
          <stddev>0.0</stddev>
        </noise>
      </ray>
      <plugin filename="libgazebo_ros_velodyne_laser.so" name="gazebo_ros_laser_controller">
        <topicName>/rs1_points</topicName>
        <frameName>rs1_frame</frameName>
        <organize_cloud>False</organize_cloud>
        <min_range>0.05</min_range>
        <max_range>130.0</max_range>
        <gaussianNoise>0.008</gaussianNoise>
      </plugin>
    </sensor>
  </gazebo>
  <!-- <xacro:hokuyo_utm30lx name="hokuyo" robot_name="hokuyo_frame" parent="base_link_husky" ros_topic="hokuyo_scan" update_rate="40" ray_count="720" min_angle="90" max_angle="-90">
        <origin xyz="0.5 0.0 0.30" rpy="0.0 0.0 0.0" />
    </xacro:hokuyo_utm30lx> -->
  <joint name="imu_link_base_mount_joint" type="fixed">
    <origin rpy="0.0 0.0 0.0" xyz="0.0 0.0 0.2"/>
    <parent link="base_link_husky"/>
    <child link="imu_link"/>
  </joint>
  <link name="imu_link">
    </link>
  <gazebo reference="imu_link">
    <gravity>true</gravity>
    <sensor name="imu_sensor" type="imu">
      <always_on>true</always_on>
      <update_rate>100</update_rate>
      <visualize>true</visualize>
      <topic>imu_topic</topic>
      <plugin filename="libgazebo_ros_imu_sensor.so" name="imu_plugin">
        <robotNamespace>MobileManipulator</robotNamespace>
        <topicName>imu_topic</topicName>
        <bodyName>imu_link</bodyName>
        <updateRateHZ>100</updateRateHZ>
        <gaussianNoise>0.0</gaussianNoise>
        <xyzOffset>0 0 0</xyzOffset>
        <rpyOffset>0 0 0</rpyOffset>
        <frameName>imu_link</frameName>
        <initialOrientationAsReference>false</initialOrientationAsReference>
      </plugin>
      <pose>0 0 0 0 0 0</pose>
    </sensor>
  </gazebo>
</robot>

